Workbook
Name ACTION: #REF!
Name ACTION: #REF!

Sheet Cover
B2: TEST REPORT DOCUMENT
A4: Project Name | B4: FengDesk AI - Intelligent Workspace Feng Shui Plant Recommendation & E-Commerce Platform | E4: Creator | F4: Vu Manh Dung
A5: Project Code | B5: SU26SE093 | E5: Issue Date | F5: 26/08/2026
A6: Document Code | B6: =B5&"_"&"Test Report"&"_"&"v1.0" -> SU26SE093_Test Report_v1.0 | E6: Version | F6: 1.0
A9: Record of change
A10: Effective Date | B10: Version | C10: Change Item | D10: *A,D,M | E10: Change description | F10: Reference
A11: 17/08/2026 | B11: 1 | C11: All sheets | D11: A | E11: Initial version of the integration test report. | F11: Report5_Test Documentation.docx
A12: 17/08/2026 | B12: 2 | C12: Authentication, Test Statistics | D12: A | E12: Added the 17 multi-step authentication cases (registration, forgot password, change of email) that were executed but not yet listed. The workbook now holds all 88 integration cases. | F12: Report5_Test Documentation.docx
A13: 26/08/2026 | B13: 3 | C13: All feature sheets, Test Statistics, Defect Log | D13: A | E13: Added the twelve business-flow modules completed in this round (catalog, 3D model queue, store and staff, user administration, scoring configuration, workspace, recommendation and review, shipping and notification, address and taxonomy, SLA pipeline, vendor liability, defect probes). Added the Defect Log: 14 defects found, 11 fixed and 3 still open. | F13: Report5_Test Documentation.docx

Sheet Test Cases
D1: TEST CASE LIST
B3: Project Name | D3: FengDesk AI - Intelligent Workspace Feng Shui Plant Recommendation & E-Commerce Platform
B4: Project Code | D4: SU26SE093
B5: Test Environment Setup Description | D5: API hosted in process over real HTTP through WebApplicationFactory, backed by a PostgreSQL database dedicated to testing. Every external integration (email, payment gateway, file storage, LLM, 3D provider, Google sign-in, speech to text, carrier) is replaced by a fake, so no test reaches a third party. Command: dotnet test FengDeskAI.slnx
B8: No | C8: Function Name | D8: Sheet Name | E8: Description | F8: Pre-Condition
B9: 1 | C9: Authentication | D9: Authentication | E9: UC-01 Register / Login. Registration, sign-in, account recovery, change of email, Google sign-in and the access token of every role. | F9: See the Pre-Condition column of each case in the feature sheet
B10: 2 | C10: Cart and Checkout | D10: Cart and Checkout | E10: UC-09, UC-10. Shopping cart, checkout and the splitting of one cart into one sub order per garden (BR-04, BR-05). | F10: See the Pre-Condition column of each case in the feature sheet
B11: 3 | C11: Payment and Cancellation | D11: Payment and Cancellation | E11: UC-11. Payment link creation for online orders and order cancellation. Real settlement is out of scope (section 1.2). | F11: See the Pre-Condition column of each case in the feature sheet
B12: 4 | C12: Delivery | D12: Delivery | E12: UC-20, UC-23. Visibility of deliveries for the garden that must fulfil them. | F12: See the Pre-Condition column of each case in the feature sheet
B13: 5 | C13: Returns Refunds and Exchanges | D13: Returns Refunds and Exchanges | E13: UC-15, UC-28, UC-29, UC-30. Return request, staff decision and refund. Photo evidence is mandatory (BR-08) and dead plants are never recalled (BR-09). | F13: See the Pre-Condition column of each case in the feature sheet
B14: 6 | C14: API Authorization and Robustness | D14: API Authorization and Robustnes | E14: Cross cutting. Generated from the routing table, so all 242 endpoints are covered and any endpoint added later is covered automatically. | F14: See the Pre-Condition column of each case in the feature sheet
B15: 7 | C15: Catalog | D15: Catalog | E15: UC-04, UC-05, UC-06. Product lifecycle, variants, images, categories, tags and the feng-shui attributes of a product. | F15: See the Pre-Condition column of each case in the feature sheet
B16: 8 | C16: 3D Model Queue | D16: 3D Model Queue | E16: UC-07. Owner requests a 3D model, platform staff generates, previews, accepts or rejects it. | F16: See the Pre-Condition column of each case in the feature sheet
B17: 9 | C17: Store and Staff | D17: Store and Staff | E17: UC-02, UC-03. Garden store self-registration, pickup address, co-owners, the staff invitation lifecycle and store statistics. | F17: See the Pre-Condition column of each case in the feature sheet
B18: 10 | C18: User Administration | D18: User Administration | E18: UC-31, UC-32. Admin searches users, locks and unlocks accounts, changes roles, revokes sessions and reads the audit trail. | F18: See the Pre-Condition column of each case in the feature sheet
B19: 11 | C19: Scoring Configuration | D19: Scoring Configuration | E19: UC-33. Manager tunes the deterministic feng-shui scoring engine: parameters, element input map, purpose modifiers and room vectors. | F19: See the Pre-Condition column of each case in the feature sheet
B20: 12 | C20: Workspace Profile | D20: Workspace Profile | E20: UC-12, UC-13. Customer describes a workspace, keeps several profiles, reads the element analysis and places purchased products into a space. | F20: See the Pre-Condition column of each case in the feature sheet
... B26: 18 | C26: Defect Probes | D26: Defect Probes | E26: Cross cutting. Each case asserts the correct behaviour of a suspected defect; a red case is a real defect recorded in the Defect Log. | F26: See the Pre-Condition column of each case in the feature sheet

Sheet Test Statistics
B1: TEST STATISTICS
B3: Project Name | C3: FengDesk AI - Intelligent Workspace Feng Shui Plant Recommendation & E-Commerce Platform | E3: Creator | H3: Vu Manh Dung
B4: Project Code | C4: SU26SE093 | E4: Reviewer/Approver
B5: Document Code | C5: =C4&"_"&"Test Report"&"_"&"v1.0" -> SU26SE093_Test Report_v1.0 | E5: Issue Date | H5: 26/08/2026
B6: Notes | C6: Release covers eighteen modules: authentication, cart and checkout, payment and cancellation, delivery, returns refunds and exchanges, API authorization and robustness, catalog, 3D model queue, store and staff, user administration, scoring configuration, workspace profile, recommendation and review, shipping and notification, address and taxonomy, SLA and refund pipeline, vendor liability, defect probes.
B10: No | C10: Module code | D10: Passed | E10: Failed | F10: Pending | G10: N/A | H10: Number of test cases
B11: 1 | C11: =Authentication!B2 -> Authentication | D11: =Authentication!B6 -> 33 | E11: =Authentication!C6 -> 0 | F11: =Authentication!D6 -> 0 | G11: =Authentication!E6 -> 0 | H11: =Authentication!B4 -> 33
B12: 2 | C12: ='Cart and Checkout'!B2 -> Cart and Checkout | D12: ='Cart and Checkout'!B6 -> 11 | E12: ='Cart and Checkout'!C6 -> 0 | F12: ='Cart and Checkout'!D6 -> 0 | G12: ='Cart and Checkout'!E6 -> 0 | H12: ='Cart and Checkout'!B4 -> 11
B13: 3 | C13: ='Payment and Cancellation'!B2 -> Payment and Cancellation | D13: ='Payment and Cancellation'!B6 -> 6 | E13: ='Payment and Cancellation'!C6 -> 0 | F13: ='Payment and Cancellation'!D6 -> 0 | G13: ='Payment and Cancellation'!E6 -> 0 | H13: ='Payment and Cancellation'!B4 -> 6
B14: 4 | C14: =Delivery!B2 -> Delivery | D14: =Delivery!B6 -> 2 | E14: =Delivery!C6 -> 0 | F14: =Delivery!D6 -> 0 | G14: =Delivery!E6 -> 0 | H14: =Delivery!B4 -> 2
B15: 5 | C15: ='Returns Refunds and Exchanges'!B2 -> Returns Refunds and Exchanges | D15: ='Returns Refunds and Exchanges'!B6 -> 15 | E15: ='Returns Refunds and Exchanges'!C6 -> 0 | F15: ='Returns Refunds and Exchanges'!D6 -> 0 | G15: ='Returns Refunds and Exchanges'!E6 -> 0 | H15: ='Returns Refunds and Exchanges'!B4 -> 15
B16: 6 | C16: ='API Authorization and Robustnes'!B2 -> API Authorization and Robustness | D16: ='API Authorization and Robustnes'!B6 -> 21 | E16: ='API Authorization and Robustnes'!C6 -> 0 | F16: ='API Authorization and Robustnes'!D6 -> 0 | G16: ='API Authorization and Robustnes'!E6 -> 0 | H16: ='API Authorization and Robustnes'!B4 -> 21
B17: 7 | C17: =Catalog!B2 -> Catalog | D17: =Catalog!B6 -> 31 | E17: =Catalog!C6 -> 0 | F17: =Catalog!D6 -> 0 | G17: =Catalog!E6 -> 0 | H17: =Catalog!B4 -> 31
B18: 8 | C18: ='3D Model Queue'!B2 -> 3D Model Queue | D18: ='3D Model Queue'!B6 -> 21 | E18: ='3D Model Queue'!C6 -> 0 | F18: ='3D Model Queue'!D6 -> 0 | G18: ='3D Model Queue'!E6 -> 0 | H18: ='3D Model Queue'!B4 -> 21
B19: 9 | C19: ='Store and Staff'!B2 -> Store and Staff | D19: ='Store and Staff'!B6 -> 32 | E19: ='Store and Staff'!C6 -> 0 | F19: ='Store and Staff'!D6 -> 0 | G19: ='Store and Staff'!E6 -> 0 | H19: ='Store and Staff'!B4 -> 32
B20: 10 | C20: ='User Administration'!B2 -> User Administration | D20: ='User Administration'!B6 -> 27 | E20: ='User Administration'!C6 -> 0 | F20: ='User Administration'!D6 -> 0 | G20: ='User Administration'!E6 -> 0 | H20: ='User Administration'!B4 -> 27
B21: 11 | C21: ='Scoring Configuration'!B2 -> Scoring Configuration | D21: ='Scoring Configuration'!B6 -> 28 | E21: ='Scoring Configuration'!C6 -> 0 | F21: ='Scoring Configuration'!D6 -> 0 | G21: ='Scoring Configuration'!E6 -> 0 | H21: ='Scoring Configuration'!B4 -> 28
B22: 12 | C22: ='Workspace Profile'!B2 -> Workspace Profile | D22: ='Workspace Profile'!B6 -> 30 | E22: ='Workspace Profile'!C6 -> 0 | F22: ='Workspace Profile'!D6 -> 0 | G22: ='Workspace Profile'!E6 -> 0 | H22: ='Workspace Profile'!B4 -> 30
B23: 13 | C23: ='Recommendation and Review'!B2 -> Recommendation and Review | D23: ='Recommendation and Review'!B6 -> 22 | E23: ='Recommendation and Review'!C6 -> 0 | F23: ='Recommendation and Review'!D6 -> 0 | G23: ='Recommendation and Review'!E6 -> 0 | H23: ='Recommendation and Review'!B4 -> 22
B24: 14 | C24: ='Shipping and Notification'!B2 -> Shipping and Notification | D24: ='Shipping and Notification'!B6 -> 20 | E24: ='Shipping and Notification'!C6 -> 0 | F24: ='Shipping and Notification'!D6 -> 0 | G24: ='Shipping and Notification'!E6 -> 0 | H24: ='Shipping and Notification'!B4 -> 20
B25: 15 | C25: ='Address and Taxonomy'!B2 -> Address and Taxonomy | D25: ='Address and Taxonomy'!B6 -> 21 | E25: ='Address and Taxonomy'!C6 -> 0 | F25: ='Address and Taxonomy'!D6 -> 0 | G25: ='Address and Taxonomy'!E6 -> 0 | H25: ='Address and Taxonomy'!B4 -> 21
B26: 16 | C26: ='SLA and Refund Pipeline'!B2 -> SLA and Refund Pipeline | D26: ='SLA and Refund Pipeline'!B6 -> 16 | E26: ='SLA and Refund Pipeline'!C6 -> 0 | F26: ='SLA and Refund Pipeline'!D6 -> 0 | G26: ='SLA and Refund Pipeline'!E6 -> 0 | H26: ='SLA and Refund Pipeline'!B4 -> 16
B27: 17 | C27: ='Vendor Liability'!B2 -> Vendor Liability | D27: ='Vendor Liability'!B6 -> 20 | E27: ='Vendor Liability'!C6 -> 0 | F27: ='Vendor Liability'!D6 -> 0 | G27: ='Vendor Liability'!E6 -> 0 | H27: ='Vendor Liability'!B4 -> 20
B28: 18 | C28: ='Defect Probes'!B2 -> Defect Probes | D28: ='Defect Probes'!B6 -> 11 | E28: ='Defect Probes'!C6 -> 3 | F28: ='Defect Probes'!D6 -> 0 | G28: ='Defect Probes'!E6 -> 0 | H28: ='Defect Probes'!B4 -> 14
C29: Sub total | D29: =SUM(D11:D28) -> 367 | E29: =SUM(E11:E28) -> 3 | F29: =SUM(F11:F28) -> 0 | G29: =SUM(G11:G28) -> 0 | H29: =SUM(H11:H28) -> 370
C31: Test coverage | E31: =(D29+E29)*100/(H29-G29) -> 100 | F31: %
C32: Test successful coverage | E32: =D29*100/(H29-G29) -> 99.189189 | F32: %

Sheet Authentication
A2: Feature | B2: Authentication | R2: Passed
A3: Test requirement | B3: UC-01 Register / Login. Registration, sign-in, account recovery, change of email, Google sign-in and the access token of every role. | R3: Failed
A4: Number of TCs | B4: =COUNTA(B11:B2031) -> 33 | R4: Pending
A5: Testing Round | B5: Passed | C5: Failed | D5: Pending | E5: N/A | R5: N/A
A6: Round 1 | B6: =COUNTIF($F$11:$F$2031,B$5) -> 33 | C6: =COUNTIF($F$11:$F$2031,C$5) -> 0 | D6: =COUNTIF($F$11:$F$2031,D$5) -> 0 | E6: =COUNTIF($F$11:$F$2031,E$5) -> 0
A7: Round 2 | B7: =COUNTIF($I$11:$I$2031,B$5) -> 33 | C7: =COUNTIF($I$11:$I$2031,C$5) -> 0 | D7: =COUNTIF($I$11:$I$2031,D$5) -> 0 | E7: =COUNTIF($I$11:$I$2031,E$5) -> 0
A8: Round 3 | B8: =COUNTIF($L$11:$L$2031,B$5) -> 0 | C8: =COUNTIF($L$11:$L$2031,C$5) -> 0 | D8: =COUNTIF($L$11:$L$2031,D$5) -> 0 | E8: =COUNTIF($L$11:$L$2031,E$5) -> 0
A10: Test Case ID | B10: Test Case Description | C10: Test Case Procedure | D10: Expected Results | E10: Pre-conditions | F10: Round 1 | G10: Test date | H10: Tester | I10: Round 2 | J10: Test date | K10: Tester | L10: Round 3 | M10: Test date | N10: Tester | O10: Note
A11: Sign in
A12: AUTH-LOGIN-01 | B12: [Normal] Sign in with a correct email and password | C12: Send POST /api/Auth/login with the correct email and password of the Customer account | D12: Returns 200 with an access token, a refresh token and the user profile | E12: A Customer account exists and is active | F12: Passed | G12: 17/08/2026 | H12: Vu Manh Dung | I12: Passed | J12: 17/08/2026 | K12: Vu Manh Dung | O12: Automated
A13: AUTH-LOGIN-02 | B13: [Abnormal] Sign in with a wrong password | C13: Send POST /api/Auth/login with the correct email but a wrong password | D13: Returns 401 with a generic message that does not reveal whether the email or the password was wrong | E13: A Customer account exists | F13: Passed | G13: 17/08/2026 | H13: Vu Manh Dung | I13: Passed | J13: 17/08/2026 | K13: Vu Manh Dung | O13: Automated
A14: AUTH-LOGIN-03 | B14: [Abnormal] Sign in with an email that is not registered | C14: Send POST /api/Auth/login with an email that was never registered | D14: Returns 401 with exactly the same message as the wrong-password case, so registered emails cannot be enumerated | E14: The email does not exist in the system | F14: Passed | G14: 17/08/2026 | H14: Vu Manh Dung | I14: Passed | J14: 17/08/2026 | K14: Vu Manh Dung | O14: Automated
A15: AUTH-LOGIN-04 | B15: [Boundary] Sign in with an empty password | C15: Send POST /api/Auth/login with an empty password string | D15: Returns 401 without raising a server error | E15: A Customer account exists | F15: Passed | G15: 17/08/2026 | H15: Vu Manh Dung | I15: Passed | J15: 17/08/2026 | K15: Vu Manh Dung | O15: Automated
A16: AUTH-LOGIN-05 | B16: [Normal] Sign in with the email in a different letter case | C16: Send POST /api/Auth/login with the email written entirely in uppercase | D16: Returns 200 because the email is normalised to lowercase before lookup | E16: A Customer account exists with a lowercase email | F16: Passed | G16: 17/08/2026 | H16: Vu Manh Dung | I16: Passed | J16: 17/08/2026 | K16: Vu Manh Dung | O16: Automated
A17: Current user
A18: AUTH-ME-01 | B18: [Abnormal] Call the current-user endpoint without signing in | C18: Send GET /api/Auth/me without a bearer token | D18: Returns 401 | E18: No Authorization header is attached | F18: Passed | G18: 17/08/2026 | H18: Vu Manh Dung | I18: Passed | J18: 17/08/2026 | K18: Vu Manh Dung | O18: Automated
A19: AUTH-ME-02 | B19: [Normal] Call the current-user endpoint with a valid token | C19: Send GET /api/Auth/me with the Customer bearer token | D19: Returns 200 with the profile of the signed-in account | E19: Signed in as the Customer account | F19: Passed | G19: 17/08/2026 | H19: Vu Manh Dung | I19: Passed | J19: 17/08/2026 | K19: Vu Manh Dung | O19: Automated
A20: Google sign-in
A21: AUTH-GOOGLE-01 | B21: [Normal] First Google sign in creates a new account | C21: Send POST /api/Auth/google with a valid Google credential for an email that has no account | D21: Returns 200 with an access token; the account is created with no password | E21: The email has never been registered | F21: Passed | G21: 17/08/2026 | H21: Vu Manh Dung | I21: Passed | J21: 17/08/2026 | K21: Vu Manh Dung | O21: Automated
A22: AUTH-GOOGLE-02 | B22: [Abnormal] A Google only account cannot sign in with a password | C22: Create an account through Google sign in, then call POST /api/Auth/login with that email | D22: Returns 401 because the account has no password yet | E22: The account was created through Google sign in | F22: Passed | G22: 17/08/2026 | H22: Vu Manh Dung | I22: Passed | J22: 17/08/2026 | K22: Vu Manh Dung | O22: Automated
A23: AUTH-GOOGLE-03 | B23: [Abnormal] An invalid Google ID token is rejected | C23: Send POST /api/Auth/google with a made up credential | D23: Returns 401 and no account is created | E23: None | F23: Passed | G23: 17/08/2026 | H23: Vu Manh Dung | I23: Passed | J23: 17/08/2026 | K23: Vu Manh Dung | O23: Automated
A24: Role tokens
A25: AUTH-TOKEN-01 | B25: [Normal] The Customer token reaches the current user endpoint | C25: Sign in as Customer, then call GET /api/Auth/me with that token | D25: Returns 200 with the profile of the Customer account | E25: A Customer account exists and is active | F25: Passed | G25: 17/08/2026 | H25: Vu Manh Dung | I25: Passed | J25: 17/08/2026 | K25: Vu Manh Dung | O25: Automated
A26: AUTH-TOKEN-02 | B26: [Normal] The Staff token reaches the current user endpoint | C26: Sign in as Staff, then call GET /api/Auth/me with that token | D26: Returns 200 with the profile of the Staff account | E26: A Staff account exists and is active | F26: Passed | G26: 17/08/2026 | H26: Vu Manh Dung | I26: Passed | J26: 17/08/2026 | K26: Vu Manh Dung | O26: Automated
A27: AUTH-TOKEN-03 | B27: [Normal] The Manager token reaches the current user endpoint | C27: Sign in as Manager, then call GET /api/Auth/me with that token | D27: Returns 200 with the profile of the Manager account | E27: A Manager account exists and is active | F27: Passed | G27: 17/08/2026 | H27: Vu Manh Dung | I27: Passed | J27: 17/08/2026 | K27: Vu Manh Dung | O27: Automated
A28: AUTH-TOKEN-04 | B28: [Normal] The Admin token reaches the current user endpoint | C28: Sign in as Admin, then call GET /api/Auth/me with that token | D28: Returns 200 with the profile of the Admin account | E28: A Admin account exists and is active | F28: Passed | G28: 17/08/2026 | H28: Vu Manh Dung | I28: Passed | J28: 17/08/2026 | K28: Vu Manh Dung | O28: Automated
A29: AUTH-TOKEN-05 | B29: [Normal] The Garden Owner token reaches the current user endpoint | C29: Sign in as Garden Owner, then call GET /api/Auth/me with that token | D29: Returns 200 with the profile of the Garden Owner account | E29: A Garden Owner account exists and is active | F29: Passed | G29: 17/08/2026 | H29: Vu Manh Dung | I29: Passed | J29: 17/08/2026 | K29: Vu Manh Dung | O29: Automated
A30: AUTH-TOKEN-06 | B30: [Abnormal] The current user endpoint refuses a request without a token | C30: Send GET /api/Auth/me with no Authorization header | D30: Returns 401 | E30: None | F30: Passed | G30: 17/08/2026 | H30: Vu Manh Dung | I30: Passed | J30: 17/08/2026 | K30: Vu Manh Dung | O30: Automated
A31: Registration
A32: AUTH-REG-01 | B32: [Normal] Complete the three-step registration with a new email | C32: Send POST /api/Auth/register/initiate with an unused email, read the OTP, send POST /api/Auth/register/verify, then POST /api/Auth/register/finalize with the registration token and a password | D32: Returns 201 with an access token, and the new account signs in immediately with that password | E32: The email has never been registered | F32: Passed | G32: 17/08/2026 | H32: Vu Manh Dung | I32: Passed | J32: 17/08/2026 | K32: Vu Manh Dung | O32: Automated
A33: AUTH-REG-02 | B33: [Abnormal] Register with an email that already has an account | C33: Send POST /api/Auth/register/initiate with the email of an existing Customer account | D33: Returns 409 and no OTP is issued | E33: A Customer account exists with that email | F33: Passed | G33: 17/08/2026 | H33: Vu Manh Dung | I33: Passed | J33: 17/08/2026 | K33: Vu Manh Dung | O33: Automated
A34: AUTH-REG-03 | B34: [Abnormal] The registration token can only be used once | C34: Complete the first two registration steps, then send POST /api/Auth/register/finalize twice with the same registration token | D34: The first call returns 201, the second returns 401 | E34: The email has never been registered | F34: Passed | G34: 17/08/2026 | H34: Vu Manh Dung | I34: Passed | J34: 17/08/2026 | K34: Vu Manh Dung | O34: Automated
A35: AUTH-REG-04 | B35: [Abnormal] Too many wrong OTP attempts lock the code | C35: Request a registration OTP, then send POST /api/Auth/register/verify six times with a wrong OTP | D35: Returns 400 with a message stating the code was tried too many times | E35: A registration OTP has just been issued | F35: Passed | G35: 17/08/2026 | H35: Vu Manh Dung | I35: Passed | J35: 17/08/2026 | K35: Vu Manh Dung | O35: Automated
A36: Forgot password
A37: AUTH-FP-01 | B37: [Normal] Send a password-reset OTP to a registered email | C37: Send POST /api/Auth/forgot-password/initiate with the email of the Customer account | D37: Returns 200 and an OTP is sent to that mailbox | E37: A Customer account exists and is active | F37: Passed | G37: 17/08/2026 | H37: Vu Manh Dung | I37: Passed | J37: 17/08/2026 | K37: Vu Manh Dung | O37: Automated
A38: AUTH-FP-02 | B38: [Abnormal] Send a password-reset OTP to an unregistered email | C38: Send POST /api/Auth/forgot-password/initiate with an email that was never registered | D38: Returns 404, a deliberate decision that favours a clear user experience over resisting email enumeration | E38: The email does not exist in the system | F38: Passed | G38: 17/08/2026 | H38: Vu Manh Dung | I38: Passed | J38: 17/08/2026 | K38: Vu Manh Dung | O38: Automated
A39: AUTH-FP-03 | B39: [Abnormal] Request an OTP with a malformed email | C39: Send POST /api/Auth/forgot-password/initiate with a string that is not an email | D39: Returns 400 with an invalid-email message | E39: None | F39: Passed | G39: 17/08/2026 | H39: Vu Manh Dung | I39: Passed | J39: 17/08/2026 | K39: Vu Manh Dung | O39: Automated
A40: AUTH-FP-04 | B40: [Boundary] Request an OTP with an empty email | C40: Send POST /api/Auth/forgot-password/initiate with an empty email string | D40: Returns 400 without raising a server error | E40: None | F40: Passed | G40: 17/08/2026 | H40: Vu Manh Dung | I40: Passed | J40: 17/08/2026 | K40: Vu Manh Dung | O40: Automated
A41: AUTH-FP-05 | B41: [Abnormal] Verify a wrong OTP | C41: Send POST /api/Auth/forgot-password/verify with an incorrect OTP | D41: Returns 400 and issues no resetPasswordToken | E41: A Customer account exists | F41: Passed | G41: 17/08/2026 | H41: Vu Manh Dung | I41: Passed | J41: 17/08/2026 | K41: Vu Manh Dung | O41: Automated
A42: AUTH-FP-06 | B42: [Abnormal] Reset the password with an invalid token | C42: Send POST /api/Auth/forgot-password/reset with a made-up resetPasswordToken | D42: Returns 401 with an invalid-session message | E42: No password-reset session is open | F42: Passed | G42: 17/08/2026 | H42: Vu Manh Dung | I42: Passed | J42: 17/08/2026 | K42: Vu Manh Dung | O42: Automated
...

Sheet Cart and Checkout
A2: Feature | B2: Cart and Checkout | R2: Passed
A3: Test requirement | B3: UC-09, UC-10. Shopping cart, checkout and the splitting of one cart into one sub order per garden (BR-04, BR-05). | R3: Failed
A4: Number of TCs | B4: =COUNTA(B11:B2004) -> 11 | R4: Pending
A5: Testing Round | B5: Passed | C5: Failed | D5: Pending | E5: N/A | R5: N/A
A6: Round 1 | B6: =COUNTIF($F$11:$F$2004,B$5) -> 11 | C6: =COUNTIF($F$11:$F$2004,C$5) -> 0 | D6: =COUNTIF($F$11:$F$2004,D$5) -> 0 | E6: =COUNTIF($F$11:$F$2004,E$5) -> 0
A7: Round 2 | B7: =COUNTIF($I$11:$I$2004,B$5) -> 11 | C7: =COUNTIF($I$11:$I$2004,C$5) -> 0 | D7: =COUNTIF($I$11:$I$2004,D$5) -> 0 | E7: =COUNTIF($I$11:$I$2004,E$5) -> 0
A8: Round 3 | B8: =COUNTIF($L$11:$L$2004,B$5) -> 0 | C8: =COUNTIF($L$11:$L$2004,C$5) -> 0 | D8: =COUNTIF($L$11:$L$2004,D$5) -> 0 | E8: =COUNTIF($L$11:$L$2004,E$5) -> 0
A10: Test Case ID | B10: Test Case Description | C10: Test Case Procedure | D10: Expected Results | E10: Pre-conditions | F10: Round 1 | G10: Test date | H10: Tester | I10: Round 2 | J10: Test date | K10: Tester | L10: Round 3 | M10: Test date | N10: Tester | O10: Note
A11: Cart
A12: SALES-CART-01 | B12: [Normal] Add a product to the cart and read the cart back | C12: Add two units of a product variant, then read GET /api/cart | D12: The cart holds one line with quantity two and the subtotal equals price times two | E12: A store with a product variant in stock exists | F12: Passed | G12: 17/08/2026 | H12: Vu Manh Dung | I12: Passed | J12: 17/08/2026 | K12: Vu Manh Dung | O12: Automated
A13: SALES-CART-02 | B13: [Abnormal] Adding to the cart with quantity zero is rejected | C13: Send POST /api/cart/items with quantity zero | D13: Returns 400 and nothing is added | E13: A store with a product variant exists | F13: Passed | G13: 17/08/2026 | H13: Vu Manh Dung | I13: Passed | J13: 17/08/2026 | K13: Vu Manh Dung | O13: Automated
A14: SALES-CART-03 | B14: [Abnormal] Adding more units than the available stock is rejected | C14: Send POST /api/cart/items with a quantity above the stock of the variant | D14: Returns 400 with a message about the remaining stock | E14: The variant has a known stock level | F14: Passed | G14: 17/08/2026 | H14: Vu Manh Dung | I14: Passed | J14: 17/08/2026 | K14: Vu Manh Dung | O14: Automated
A15: SALES-CART-04 | B15: [Abnormal] Adding an unknown product variant returns not found | C15: Send POST /api/cart/items with an identifier that does not exist | D15: Returns 404 | E15: None | F15: Passed | G15: 17/08/2026 | H15: Vu Manh Dung | I15: Passed | J15: 17/08/2026 | K15: Vu Manh Dung | O15: Automated
A16: Checkout
A17: SALES-ORDER-01 | B17: [Normal] A cart spanning two stores splits into two deliveries | C17: Add one product of store A and one of store B, then check out with cash on delivery | D17: The order is created with two deliveries, one per store, each with its own subtotal | E17: Two stores each with a product variant in stock, and a default shipping address | F17: Passed | G17: 17/08/2026 | H17: Vu Manh Dung | I17: Passed | J17: 17/08/2026 | K17: Vu Manh Dung | O17: Automated
A18: SALES-ORDER-02 | B18: [Normal] A cart from a single store creates one delivery | C18: Add one product of a single store, then check out | D18: The order is created with exactly one delivery | E18: One store with a product variant in stock | F18: Passed | G18: 17/08/2026 | H18: Vu Manh Dung | I18: Passed | J18: 17/08/2026 | K18: Vu Manh Dung | O18: Automated
A19: SALES-ORDER-03 | B19: [Abnormal] Checking out an empty cart is rejected | C19: Empty the cart, then send POST /api/orders | D19: Returns 400 and no order is created | E19: The cart is empty | F19: Passed | G19: 17/08/2026 | H19: Vu Manh Dung | I19: Passed | J19: 17/08/2026 | K19: Vu Manh Dung | O19: Automated
A20: SALES-ORDER-04 | B20: [Abnormal] Checkout with an unknown shipping address is rejected | C20: Add a product, then check out with a shipping address identifier that does not exist | D20: Returns 400 and no order is created | E20: The cart holds at least one line | F20: Passed | G20: 17/08/2026 | H20: Vu Manh Dung | I20: Passed | J20: 17/08/2026 | K20: Vu Manh Dung | O20: Automated
A21: SALES-ORDER-05 | B21: [Normal] Ordered items are removed from the cart after checkout | C21: Add a product, check out, then read GET /api/cart | D21: The cart is empty | E21: The cart holds exactly the products being ordered | F21: Passed | G21: 17/08/2026 | H21: Vu Manh Dung | I21: Passed | J21: 17/08/2026 | K21: Vu Manh Dung | O21: Automated
A22: SALES-ORDER-06 | B22: [Normal] A placed order appears in the customer order history | C22: Place an order, then read GET /api/orders and GET /api/orders/{id} | D22: The order appears in the list and its detail can be opened | E22: The customer has placed at least one order | F22: Passed | G22: 17/08/2026 | H22: Vu Manh Dung | I22: Passed | J22: 17/08/2026 | K22: Vu Manh Dung | O22: Automated
A23: SALES-ORDER-07 | B23: [Abnormal] An order is not visible to another customer | C23: Place an order as customer A, register customer B, then read the order as customer B | D23: Returns 404 for customer B | E23: Two separate customer accounts exist | F23: Passed | G23: 17/08/2026 | H23: Vu Manh Dung | I23: Passed | J23: 17/08/2026 | K23: Vu Manh Dung | O23: Automated

Sheet Payment and Cancellation
A2: Feature | B2: Payment and Cancellation | R2: Passed
A3: Test requirement | B3: UC-11. Payment link creation for online orders and order cancellation. Real settlement is out of scope (section 1.2). | R3: Failed
A4: Number of TCs | B4: =COUNTA(B11:B1999) -> 6 | R4: Pending
A5: Testing Round | B5: Passed | C5: Failed | D5: Pending | E5: N/A | R5: N/A
A6: Round 1 | B6: =COUNTIF($F$11:$F$1999,B$5) -> 6 | C6: =COUNTIF($F$11:$F$1999,C$5) -> 0 | D6: =COUNTIF($F$11:$F$1999,D$5) -> 0 | E6: =COUNTIF($F$11:$F$1999,E$5) -> 0
A7: Round 2 | B7: =COUNTIF($I$11:$I$1999,B$5) -> 6 | C7: =COUNTIF($I$11:$I$1999,C$5) -> 0 | D7: =COUNTIF($I$11:$I$1999,D$5) -> 0 | E7: =COUNTIF($I$11:$I$1999,E$5) -> 0
A8: Round 3 | B8: =COUNTIF($L$11:$L$1999,B$5) -> 0 | C8: =COUNTIF($L$11:$L$1999,C$5) -> 0 | D8: =COUNTIF($L$11:$L$1999,D$5) -> 0 | E8: =COUNTIF($L$11:$L$1999,E$5) -> 0
A10: Test Case ID | B10: Test Case Description | C10: Test Case Procedure | D10: Expected Results | E10: Pre-conditions | F10: Round 1 | G10: Test date | H10: Tester | I10: Round 2 | J10: Test date | K10: Tester | L10: Round 3 | M10: Test date | N10: Tester | O10: Note
A11: Payment
A12: SALES-PAY-01 | B12: [Normal] Create a payment link for an online order | C12: Place an order with the online payment method, then send POST /api/payments/{orderId} | D12: Returns a checkout link for the order | E12: An order awaiting online payment exists | F12: Passed | G12: 17/08/2026 | H12: Vu Manh Dung | I12: Passed | J12: 17/08/2026 | K12: Vu Manh Dung | O12: Automated
A13: SALES-PAY-02 | B13: [Abnormal] A cash on delivery order cannot create an online payment link | C13: Place a cash on delivery order, then send POST /api/payments/{orderId} | D13: Returns 400 with a message that a cash order is paid on delivery | E13: A cash on delivery order exists | F13: Passed | G13: 17/08/2026 | H13: Vu Manh Dung | I13: Passed | J13: 17/08/2026 | K13: Vu Manh Dung | O13: Automated
A14: SALES-PAY-03 | B14: [Abnormal] Creating a payment link for an unknown order returns not found | C14: Send POST /api/payments/{orderId} with an identifier that does not exist | D14: Returns 404 | E14: None | F14: Passed | G14: 17/08/2026 | H14: Vu Manh Dung | I14: Passed | J14: 17/08/2026 | K14: Vu Manh Dung | O14: Automated
A15: SALES-PAY-04 | B15: [Abnormal] The payment webhook survives a malformed payload | C15: Send POST /api/payments/payos/webhook with a body that does not match the expected shape | D15: Answers with a client error, never with a server error | E15: None | F15: Passed | G15: 17/08/2026 | H15: Vu Manh Dung | I15: Passed | J15: 17/08/2026 | K15: Vu Manh Dung | O15: Automated
A16: Cancellation
A17: SALES-CANCEL-01 | B17: [Normal] Cancel an order while it is still pending | C17: Place an order, then send POST /api/orders/{id}/cancel | D17: The order moves to the cancelled state | E17: An order in the pending state exists | F17: Passed | G17: 17/08/2026 | H17: Vu Manh Dung | I17: Passed | J17: 17/08/2026 | K17: Vu Manh Dung | O17: Automated
A18: SALES-CANCEL-02 | B18: [Abnormal] Cancelling the same order twice is rejected | C18: Cancel an order, then cancel it again | D18: The second call is refused | E18: An order that has already been cancelled | F18: Passed | G18: 17/08/2026 | H18: Vu Manh Dung | I18: Passed | J18: 17/08/2026 | K18: Vu Manh Dung | O18: Automated

Sheet Delivery
A2: Feature | B2: Delivery | R2: Passed
A3: Test requirement | B3: UC-20, UC-23. Visibility of deliveries for the garden that must fulfil them. | R3: Failed
A4: Number of TCs | B4: =COUNTA(B11:B1993) -> 2 | R4: Pending
A5: Testing Round | B5: Passed | C5: Failed | D5: Pending | E5: N/A | R5: N/A
A6: Round 1 | B6: =COUNTIF($F$11:$F$1993,B$5) -> 2 | C6: =COUNTIF($F$11:$F$1993,C$5) -> 0 | D6: =COUNTIF($F$11:$F$1993,D$5) -> 0 | E6: =COUNTIF($F$11:$F$1993,E$5) -> 0
A7: Round 2 | B7: =COUNTIF($I$11:$I$1993,B$5) -> 2 | C7: =COUNTIF($I$11:$I$1993,C$5) -> 0 | D7: =COUNTIF($I$11:$I$1993,D$5) -> 0 | E7: =COUNTIF($I$11:$I$1993,E$5) -> 0
A8: Round 3 | B8: =COUNTIF($L$11:$L$1993,B$5) -> 0 | C8: =COUNTIF($L$11:$L$1993,C$5) -> 0 | D8: =COUNTIF($L$11:$L$1993,D$5) -> 0 | E8: =COUNTIF($L$11:$L$1993,E$5) -> 0
A10: Test Case ID | B10: Test Case Description | C10: Test Case Procedure | D10: Expected Results | E10: Pre-conditions | F10: Round 1 | G10: Test date | H10: Tester | I10: Round 2 | J10: Test date | K10: Tester | L10: Round 3 | M10: Test date | N10: Tester | O10: Note
A11: SALES-DELIVERY-01 | B11: [Normal] A store owner can list the deliveries of their own store | C11: Place an order against the store, then read GET /api/orders/stores/{storeId}/deliveries as the owner | D11: Returns 200 with the deliveries of that store | E11: The store has at least one delivery | F11: Passed | G11: 17/08/2026 | H11: Vu Manh Dung | I11: Passed | J11: 17/08/2026 | K11: Vu Manh Dung | O11: Automated
A12: SALES-DELIVERY-02 | B12: [Abnormal] A customer cannot list the deliveries of a store | C12: Read GET /api/orders/stores/{storeId}/deliveries with a customer token | D12: Returns 403 or 401 | E12: A store exists | F12: Passed | G12: 17/08/2026 | H12: Vu Manh Dung | I12: Passed | J12: 17/08/2026 | K12: Vu Manh Dung | O12: Automated

Sheet Returns Refunds and Exchanges
A2: Feature | B2: Returns Refunds and Exchanges | R2: Passed
A3: Test requirement | B3: UC-15, UC-28, UC-29, UC-30. Return request, staff decision and refund. Photo evidence is mandatory (BR-08) and dead plants are never recalled (BR-09). | R3: Failed
A4: Number of TCs | B4: =COUNTA(B11:B2006) -> 15 | R4: Pending
A5: Testing Round | B5: Passed | C5: Failed | D5: Pending | E5: N/A | R5: N/A
A6: Round 1 | B6: =COUNTIF($F$11:$F$2006,B$5) -> 15 | C6: =COUNTIF($F$11:$F$2006,C$5) -> 0 | D6: =COUNTIF($F$11:$F$2006,D$5) -> 0 | E6: =COUNTIF($F$11:$F$2006,E$5) -> 0
A7: Round 2 | B7: =COUNTIF($I$11:$I$2006,B$5) -> 15 | C7: =COUNTIF($I$11:$I$2006,C$5) -> 0 | D7: =COUNTIF($I$11:$I$2006,D$5) -> 0 | E7: =COUNTIF($I$11:$I$2006,E$5) -> 0
A8: Round 3 | B8: =COUNTIF($L$11:$L$2006,B$5) -> 0 | C8: =COUNTIF($L$11:$L$2006,C$5) -> 0 | D8: =COUNTIF($L$11:$L$2006,D$5) -> 0 | E8: =COUNTIF($L$11:$L$2006,E$5) -> 0
A10: Test Case ID | B10: Test Case Description | C10: Test Case Procedure | D10: Expected Results | E10: Pre-conditions | F10: Round 1 | G10: Test date | H10: Tester | I10: Round 2 | J10: Test date | K10: Tester | L10: Round 3 | M10: Test date | N10: Tester | O10: Note
A11: RMA-01 | B11: [Normal] A customer opens a return request on a delivered order | C11: Drive an order to the delivered state, then send POST /api/returns with evidence images | D11: The request is created in the Requested state | E11: An order whose delivery reached the delivered state | F11: Passed | G11: 17/08/2026 | H11: Vu Manh Dung | I11: Passed | J11: 17/08/2026 | K11: Vu Manh Dung | O11: Automated
A12: RMA-02 | B12: [Abnormal] A return request without evidence images is rejected | C12: Send POST /api/returns with an empty list of image URLs | D12: Returns 400 with a message that evidence is required | E12: An order whose delivery reached the delivered state | F12: Passed | G12: 17/08/2026 | H12: Vu Manh Dung | I12: Passed | J12: 17/08/2026 | K12: Vu Manh Dung | O12: Automated
A13: RMA-03 | B13: [Abnormal] A return request on a delivery that was never delivered is rejected | C13: Place an order and, without advancing the delivery, send POST /api/returns | D13: Returns 400 | E13: An order whose delivery is still pending | F13: Passed | G13: 17/08/2026 | H13: Vu Manh Dung | I13: Passed | J13: 17/08/2026 | K13: Vu Manh Dung | O13: Automated
A14: RMA-04 | B14: [Abnormal] Returning more units than were delivered is rejected | C14: Send POST /api/returns with a quantity above the delivered quantity | D14: Returns 400 | E14: A delivered order of a known quantity | F14: Passed | G14: 17/08/2026 | H14: Vu Manh Dung | I14: Passed | J14: 17/08/2026 | K14: Vu Manh Dung | O14: Automated
A15: RMA-05 | B15: [Boundary] Returning zero units is rejected | C15: Send POST /api/returns with quantity zero | D15: Returns 400 | E15: A delivered order | F15: Passed | G15: 17/08/2026 | H15: Vu Manh Dung | I15: Passed | J15: 17/08/2026 | K15: Vu Manh Dung | O15: Automated
A16: RMA-06 | B16: [Normal] A customer cancels their own request while it is still pending | C16: Open a request, then send POST /api/returns/{id}/cancel | D16: The request moves to the cancelled state | E16: A request in the Requested state | F16: Passed | G16: 17/08/2026 | H16: Vu Manh Dung | I16: Passed | J16: 17/08/2026 | K16: Vu Manh Dung | O16: Automated
A17: RMA-07 | B17: [Abnormal] Cancelling the same request twice is rejected | C17: Cancel a request, then cancel it again | D17: The second call is refused with 400 or 409 | E17: A request that has already been cancelled | F17: Passed | G17: 17/08/2026 | H17: Vu Manh Dung | I17: Passed | J17: 17/08/2026 | K17: Vu Manh Dung | O17: Automated
A18: RMA-08 | B18: [Normal] Platform staff accepts the request for review | C18: Send POST /api/returns/{id}/accept with a staff token | D18: The request leaves the Requested state | E18: A request in the Requested state | F18: Passed | G18: 17/08/2026 | H18: Vu Manh Dung | I18: Passed | J18: 17/08/2026 | K18: Vu Manh Dung | O18: Automated
A19: RMA-09 | B19: [Normal] Platform staff rejects the request with a reason | C19: Accept the request, then send POST /api/returns/{id}/reject with a reason | D19: The request moves to the rejected state | E19: A request that staff has accepted | F19: Passed | G19: 17/08/2026 | H19: Vu Manh Dung | I19: Passed | J19: 17/08/2026 | K19: Vu Manh Dung | O19: Automated
A20: RMA-10 | B20: [Abnormal] Rejecting without a reason is refused | C20: Send POST /api/returns/{id}/reject with an empty reason | D20: Returns 400 | E20: A request that staff has accepted | F20: Passed | G20: 17/08/2026 | H20: Vu Manh Dung | I20: Passed | J20: 17/08/2026 | K20: Vu Manh Dung | O20: Automated
A21: RMA-11 | B21: [Normal] A dead plant refund reaches the refunding stage without recalling the goods | C21: Accept a PlantHealth request, then send POST /api/returns/{id}/approve-refund | D21: The request reaches Refunding or Completed and never passes through the physical return states | E21: A PlantHealth request that staff has accepted | F21: Passed | G21: 17/08/2026 | H21: Vu Manh Dung | I21: Passed | J21: 17/08/2026 | K21: Vu Manh Dung | O21: Automated
A22: RMA-12 | B22: [Abnormal] A customer cannot accept their own return request | C22: Send POST /api/returns/{id}/accept with the customer token | D22: Returns 403 | E22: A request opened by that customer | F22: Passed | G22: 17/08/2026 | H22: Vu Manh Dung | I22: Passed | J22: 17/08/2026 | K22: Vu Manh Dung | O22: Automated
... A25: RMA-15 | B25: [Normal] Platform staff can list the pending return requests | C25: Read GET /api/returns/pending with a staff token | D25: Returns 200 with the queue of pending requests | E25: At least one request is waiting | F25: Passed | G25: 17/08/2026 | H25: Vu Manh Dung | I25: Passed | J25: 17/08/2026 | K25: Vu Manh Dung | O25: Automated

Sheet API Authorization and Robustnes
A2: Feature | B2: API Authorization and Robustness | R2: Passed
A3: Test requirement | B3: Cross cutting. Generated from the routing table, so all 242 endpoints are covered and any endpoint added later is covered automatically. | R3: Failed
A4: Number of TCs | B4: =COUNTA(B11:B2016) -> 21 | R4: Pending
A5: Testing Round | B5: Passed | C5: Failed | D5: Pending | E5: N/A | R5: N/A
A6: Round 1 | B6: =COUNTIF($F$11:$F$2016,B$5) -> 21 | C6: =COUNTIF($F$11:$F$2016,C$5) -> 0 | D6: =COUNTIF($F$11:$F$2016,D$5) -> 0 | E6: =COUNTIF($F$11:$F$2016,E$5) -> 0
A7: Round 2 | B7: =COUNTIF($I$11:$I$2016,B$5) -> 21 | C7: =COUNTIF($I$11:$I$2016,C$5) -> 0 | D7: =COUNTIF($I$11:$I$2016,D$5) -> 0 | E7: =COUNTIF($I$11:$I$2016,E$5) -> 0
A8: Round 3 | B8: =COUNTIF($L$11:$L$2016,B$5) -> 0 | C8: =COUNTIF($L$11:$L$2016,C$5) -> 0 | D8: =COUNTIF($L$11:$L$2016,D$5) -> 0 | E8: =COUNTIF($L$11:$L$2016,E$5) -> 0
A10: Test Case ID | B10: Test Case Description | C10: Test Case Procedure | D10: Expected Results | E10: Pre-conditions | F10: Round 1 | G10: Test date | H10: Tester | I10: Round 2 | J10: Test date | K10: Tester | L10: Round 3 | M10: Test date | N10: Tester | O10: Note
A11: Authorization matrix
A12: API-AUTHZ-01 | B12: [Normal] The routing table is discovered and is not empty | C12: Read the action descriptors of the running application | D12: 242 endpoints are discovered | E12: The application is running | F12: Passed | G12: 17/08/2026 | H12: Vu Manh Dung | I12: Passed | J12: 17/08/2026 | K12: Vu Manh Dung | O12: Automated
A13: API-AUTHZ-02 | B13: [Normal] Every protected endpoint refuses a request without a token, normal data | C13: Call all 210 protected endpoints with no Authorization header, using well formed route values | D13: Every one answers 401 | E13: The application is running | F13: Passed | G13: 17/08/2026 | H13: Vu Manh Dung | I13: Passed | J13: 17/08/2026 | K13: Vu Manh Dung | O13: Automated
A14: API-AUTHZ-03 | B14: [Boundary] Every protected endpoint refuses a request without a token, boundary data | C14: Repeat the sweep with boundary route values such as an all zero identifier | D14: Every one still answers 401, so authorization does not depend on the payload | E14: The application is running | F14: Passed | G14: 17/08/2026 | H14: Vu Manh Dung | I14: Passed | J14: 17/08/2026 | K14: Vu Manh Dung | O14: Automated
A15: API-AUTHZ-04 | B15: [Normal] Every policy protected endpoint refuses a disallowed role, normal data | C15: Call all 66 policy protected endpoints with a role the policy does not allow | D15: Every one answers 403 | E15: A token exists for each of the five roles | F15: Passed | G15: 17/08/2026 | H15: Vu Manh Dung | I15: Passed | J15: 17/08/2026 | K15: Vu Manh Dung | O15: Automated
A16: API-AUTHZ-05 | B16: [Boundary] Every policy protected endpoint refuses a disallowed role, boundary data | C16: Repeat the sweep with boundary route values | D16: Every one still answers 403 | E16: A token exists for each of the five roles | F16: Passed | G16: 17/08/2026 | H16: Vu Manh Dung | I16: Passed | J16: 17/08/2026 | K16: Vu Manh Dung | O16: Automated
A17: API-AUTHZ-06 | B17: [Normal] No public endpoint is refused, normal data | C17: Call all 26 public endpoints with no token | D17: None answers 401 or 403 | E17: The application is running | F17: Passed | G17: 17/08/2026 | H17: Vu Manh Dung | I17: Passed | J17: 17/08/2026 | K17: Vu Manh Dung | O17: Automated
A18: API-AUTHZ-07 | B18: [Boundary] No public endpoint is refused, boundary data | C18: Repeat the sweep with boundary route values | D18: None answers 401 or 403 | E18: The application is running | F18: Passed | G18: 17/08/2026 | H18: Vu Manh Dung | I18: Passed | J18: 17/08/2026 | K18: Vu Manh Dung | O18: Automated
A19: Smoke test
A20: API-SMOKE-01 | B20: [Normal] No parameterless read endpoint answers with a server error | C20: Call all 47 GET endpoints that take no route parameter with an administrator token | D20: None answers with a 5xx status | E20: The database has been migrated and seeded | F20: Passed | G20: 17/08/2026 | H20: Vu Manh Dung | I20: Passed | J20: 17/08/2026 | K20: Vu Manh Dung | O20: Automated
A21: API-SMOKE-02 | B21: [Normal] The API documentation is generated | C21: Read the OpenAPI document of the application | D21: The document is produced, so no route is duplicated | E21: The application is running | F21: Passed | G21: 17/08/2026 | H21: Vu Manh Dung | I21: Passed | J21: 17/08/2026 | K21: Vu Manh Dung | O21: Automated
A22: Robustness
A23: API-ROBUST-01 | B23: [Normal] Normal data never causes a server error | C23: Call all 242 endpoints with well formed data | D23: No endpoint answers with a 5xx status | E23: The application is running | F23: Passed | G23: 17/08/2026 | H23: Vu Manh Dung | I23: Passed | J23: 17/08/2026 | K23: Vu Manh Dung | O23: Automated
A24: API-ROBUST-02 | B24: [Boundary] Boundary data never causes a server error | C24: Call all 242 endpoints with boundary values such as an all zero identifier and empty fields | D24: No endpoint answers with a 5xx status | E24: The application is running | F24: Passed | G24: 17/08/2026 | H24: Vu Manh Dung | I24: Passed | J24: 17/08/2026 | K24: Vu Manh Dung | O24: Automated
A25: API-ROBUST-03 | B25: [Abnormal] Malformed data never causes a server error | C25: Call all 242 endpoints with invalid identifiers, invalid JSON, negative quantities and SQL syntax | D25: Every endpoint answers with a client error, none with a 5xx status | E25: The application is running | F25: Passed | G25: 17/08/2026 | H25: Vu Manh Dung | I25: Passed | J25: 17/08/2026 | K25: Vu Manh Dung | O25: Automated
A26: Environment guard
A27: ENV-GUARD-01 | B27: [Normal] A connection string pointing at localhost is accepted | C27: Start the suite with Host=localhost | D27: The suite runs | E27: None | F27: Passed | G27: 17/08/2026 | H27: Vu Manh Dung | I27: Passed | J27: 17/08/2026 | K27: Vu Manh Dung | O27: Automated
A28: ENV-GUARD-02 | B28: [Normal] A connection string pointing at 127.0.0.1 is accepted | C28: Start the suite with Host=127.0.0.1 | D28: The suite runs | E28: None | F28: Passed | G28: 17/08/2026 | H28: Vu Manh Dung | I28: Passed | J28: 17/08/2026 | K28: Vu Manh Dung | O28: Automated
A29: ENV-GUARD-03 | B29: [Normal] A connection string using the container host name is accepted | C29: Start the suite with Server=postgres, as used on the CI runner | D29: The suite runs | E29: None | F29: Passed | G29: 17/08/2026 | H29: Vu Manh Dung | I29: Passed | J29: 17/08/2026 | K29: Vu Manh Dung | O29: Automated
A30: ENV-GUARD-04 | B30: [Abnormal] A production database connection is refused | C30: Start the suite with a connection string pointing at the Supabase production host | D30: The suite stops before touching the database | E30: None | F30: Passed | G30: 17/08/2026 | H30: Vu Manh Dung | I30: Passed | J30: 17/08/2026 | K30: Vu Manh Dung | O30: Automated
A31: ENV-GUARD-05 | B31: [Abnormal] Any other remote host is refused | C31: Start the suite with a connection string pointing at an arbitrary remote host | D31: The suite stops before touching the database | E31: None | F31: Passed | G31: 17/08/2026 | H31: Vu Manh Dung | I31: Passed | J31: 17/08/2026 | K31: Vu Manh Dung | O31: Automated
A32: ENV-GUARD-06 | B32: [Abnormal] A missing connection string stops the suite with guidance | C32: Start the suite with the setting absent | D32: The suite stops and prints the two supported ways to configure it | E32: None | F32: Passed | G32: 17/08/2026 | H32: Vu Manh Dung | I32: Passed | J32: 17/08/2026 | K32: Vu Manh Dung | O32: Automated
A33: ENV-GUARD-07 | B33: [Boundary] An empty connection string is refused | C33: Start the suite with an empty setting | D33: The suite stops with the same guidance | E33: None | F33: Passed | G33: 17/08/2026 | H33: Vu Manh Dung | I33: Passed | J33: 17/08/2026 | K33: Vu Manh Dung | O33: Automated
A34: ENV-GUARD-08 | B34: [Boundary] A whitespace only connection string is refused | C34: Start the suite with a setting containing only spaces | D34: The suite stops with the same guidance | E34: None | F34: Passed | G34: 17/08/2026 | H34: Vu Manh Dung | I34: Passed | J34: 17/08/2026 | K34: Vu Manh Dung | O34: Automated
A35: ENV-GUARD-09 | B35: [Abnormal] A connection string with no host segment is refused | C35: Start the suite with a connection string that declares no host | D35: The suite stops before touching the database | E35: None | F35: Passed | G35: 17/08/2026 | H35: Vu Manh Dung | I35: Passed | J35: 17/08/2026 | K35: Vu Manh Dung | O35: Automated

Sheet Catalog
A2: Feature | B2: Catalog | R2: Passed
A3: Test requirement | B3: UC-04, UC-05, UC-06. Product lifecycle, variants, images, categories, tags and the feng-shui attributes of a product. | R3: Failed
A4: Number of TCs | B4: =COUNTA(B11:B2022) -> 31 | R4: Pending
A5: Testing Round | B5: Passed | C5: Failed | D5: Pending | E5: N/A | R5: N/A
A6: Round 1 | B6: =COUNTIF($F$11:$F$2022,B$5) -> 31 | C6: =COUNTIF($F$11:$F$2022,C$5) -> 0 | D6: =COUNTIF($F$11:$F$2022,D$5) -> 0 | E6: =COUNTIF($F$11:$F$2022,E$5) -> 0
A7: Round 2 | B7: =COUNTIF($I$11:$I$2022,B$5) -> 31 | C7: =COUNTIF($I$11:$I$2022,C$5) -> 0 | D7: =COUNTIF($I$11:$I$2022,D$5) -> 0 | E7: =COUNTIF($I$11:$I$2022,E$5) -> 0
A8: Round 3 | B8: =COUNTIF($L$11:$L$2022,B$5) -> 0 | C8: =COUNTIF($L$11:$L$2022,C$5) -> 0 | D8: =COUNTIF($L$11:$L$2022,D$5) -> 0 | E8: =COUNTIF($L$11:$L$2022,E$5) -> 0
A10: Test Case ID | B10: Test Case Description | C10: Test Case Procedure | D10: Expected Results | E10: Pre-conditions | F10: Round 1 | G10: Test date | H10: Tester | I10: Round 2 | J10: Test date | K10: Tester | L10: Round 3 | M10: Test date | N10: Tester | O10: Note
A11: CAT-01 | B11: [Normal] A store owner creates a product with one variant | C11: Send POST /api/products as a garden owner | D11: Returns 201 Created and name = Kim tiền để bàn | E11: A store owned by the garden-owner test user, seeded with a product | F11: Passed | G11: 26/08/2026 | H11: Vu Manh Dung | I11: Passed | J11: 26/08/2026 | K11: Vu Manh Dung | O11: Automated
A12: CAT-02 | B12: [Abnormal] Creating a product with a blank name is rejected | C12: Send POST /api/products as a garden owner | D12: Returns 400 Bad Request | E12: A store owned by the garden-owner test user, seeded with a product | F12: Passed | G12: 26/08/2026 | H12: Vu Manh Dung | I12: Passed | J12: 26/08/2026 | K12: Vu Manh Dung | O12: Automated
A13: CAT-03 | B13: [Abnormal] A customer cannot create a product for someone else's store | C13: Send POST /api/products as a customer | D13: Returns 403 Forbidden | E13: A store owned by the garden-owner test user, seeded with a product | F13: Passed | G13: 26/08/2026 | H13: Vu Manh Dung | I13: Passed | J13: 26/08/2026 | K13: Vu Manh Dung | O13: Automated
A14: CAT-04 | B14: [Abnormal] Creating a product with an unknown category is rejected | C14: Send POST /api/products as a garden owner | D14: Returns 400 Bad Request | E14: A store owned by the garden-owner test user, seeded with a product | F14: Passed | G14: 26/08/2026 | H14: Vu Manh Dung | I14: Passed | J14: 26/08/2026 | K14: Vu Manh Dung | O14: Automated
A15: CAT-05 | B15: [Normal] A newly created product is readable anonymously | C15: Send GET /api/products/{id} as an anonymous caller | D15: Returns 200 OK and id matches productId | E15: A product owned by the caller | F15: Passed | G15: 26/08/2026 | H15: Vu Manh Dung | I15: Passed | J15: 26/08/2026 | K15: Vu Manh Dung | O15: Automated
A16: CAT-06 | B16: [Abnormal] Reading an unknown product returns 404 | C16: Send GET /api/products/{id} as an anonymous caller | D16: Returns 404 Not Found | E16: None | F16: Passed | G16: 26/08/2026 | H16: Vu Manh Dung | I16: Passed | J16: 26/08/2026 | K16: Vu Manh Dung | O16: Automated
A17: CAT-07 | B17: [Normal] The owner updates a product and the change is persisted | C17: Send PUT /api/products/{id} as an anonymous caller | D17: Returns 200 OK and name = Tên đã đổi | E17: A product owned by the caller | F17: Passed | G17: 26/08/2026 | H17: Vu Manh Dung | I17: Passed | J17: 26/08/2026 | K17: Vu Manh Dung | O17: Automated
A18: CAT-08 | B18: [Abnormal] A customer cannot update a product they do not own | C18: Send PUT /api/products/{id} as a customer | D18: Returns 403 Forbidden | E18: A product owned by the caller | F18: Passed | G18: 26/08/2026 | H18: Vu Manh Dung | I18: Passed | J18: 26/08/2026 | K18: Vu Manh Dung | O18: Automated
A19: CAT-09 | B19: [Normal] Deleting a product removes it from the public detail endpoint | C19: Send DELETE /api/products/{id} as an anonymous caller | D19: Returns 200 OK | E19: A product owned by the caller | F19: Passed | G19: 26/08/2026 | H19: Vu Manh Dung | I19: Passed | J19: 26/08/2026 | K19: Vu Manh Dung | O19: Automated
A20: CAT-10 | B20: [Normal] The owner adds a variant to an existing product | C20: Send POST /api/products/{id}/items as a garden owner | D20: Returns 201 Created and price matches 500_000m | E20: A product owned by the caller | F20: Passed | G20: 26/08/2026 | H20: Vu Manh Dung | I20: Passed | J20: 26/08/2026 | K20: Vu Manh Dung | O20: Automated
A21: CAT-11 | B21: [Abnormal] A variant with a negative price is rejected | C21: Send POST /api/products/{id}/items as a garden owner | D21: Returns 400 Bad Request | E21: A product owned by the caller | F21: Passed | G21: 26/08/2026 | H21: Vu Manh Dung | I21: Passed | J21: 26/08/2026 | K21: Vu Manh Dung | O21: Automated
A22: CAT-12 | B22: [Abnormal] Reusing an existing SKU on another variant is rejected | C22: Send POST /api/products/{id}/items as a garden owner | D22: Returns 201 Created | E22: A product owned by the caller | F22: Passed | G22: 26/08/2026 | H22: Vu Manh Dung | I22: Passed | J22: 26/08/2026 | K22: Vu Manh Dung | O22: Automated
... A41: CAT-31 | B41: [Abnormal] A plain customer cannot create a tag | C41: Send POST /api/categories as a customer | D41: Returns 403 Forbidden | E41: A product owned by the caller | F41: Passed | G41: 26/08/2026 | H41: Vu Manh Dung | I41: Passed | J41: 26/08/2026 | K41: Vu Manh Dung | O41: Automated

Sheet 3D Model Queue
A2: Feature | B2: 3D Model Queue | R2: Passed
A3: Test requirement | B3: UC-07. Owner requests a 3D model, platform staff generates, previews, accepts or rejects it. | R3: Failed
A4: Number of TCs | B4: =COUNTA(B11:B2012) -> 21 | R4: Pending
A5: Testing Round | B5: Passed | C5: Failed | D5: Pending | E5: N/A | R5: N/A
A6: Round 1 | B6: =COUNTIF($F$11:$F$2012,B$5) -> 21 | C6: =COUNTIF($F$11:$F$2012,C$5) -> 0 | D6: =COUNTIF($F$11:$F$2012,D$5) -> 0 | E6: =COUNTIF($F$11:$F$2012,E$5) -> 0
A7: Round 2 | B7: =COUNTIF($I$11:$I$2012,B$5) -> 21 | C7: =COUNTIF($I$11:$I$2012,C$5) -> 0 | D7: =COUNTIF($I$11:$I$2012,D$5) -> 0 | E7: =COUNTIF($I$11:$I$2012,E$5) -> 0
A8: Round 3 | B8: =COUNTIF($L$11:$L$2012,B$5) -> 0 | C8: =COUNTIF($L$11:$L$2012,C$5) -> 0 | D8: =COUNTIF($L$11:$L$2012,D$5) -> 0 | E8: =COUNTIF($L$11:$L$2012,E$5) -> 0
A10: Test Case ID | B10: Test Case Description | C10: Test Case Procedure | D10: Expected Results | E10: Pre-conditions | F10: Round 1 | G10: Test date | H10: Tester | I10: Round 2 | J10: Test date | K10: Tester | L10: Round 3 | M10: Test date | N10: Tester | O10: Note
A11: M3D-01 | B11: [Normal] A store owner requests a 3D model and it lands in the staff queue | C11: See the test method for the exact call sequence | D11: Returns 202 Accepted and status = AwaitingStaff, requestType = Initial | E11: A product owned by the caller, carrying at least one image | F11: Passed | G11: 26/08/2026 | H11: Vu Manh Dung | I11: Passed | J11: 26/08/2026 | K11: Vu Manh Dung | O11: Automated
A12: M3D-02 | B12: [Abnormal] Requesting a 3D model for a product without images is rejected | C12: See the test method for the exact call sequence | D12: Returns 400 Bad Request | E12: A product owned by the caller | F12: Passed | G12: 26/08/2026 | H12: Vu Manh Dung | I12: Passed | J12: 26/08/2026 | K12: Vu Manh Dung | O12: Automated
A13: M3D-03 | B13: [Abnormal] A second open request for the same image returns 409 | C13: See the test method for the exact call sequence | D13: Returns 202 Accepted | E13: A product owned by the caller, carrying at least one image | F13: Passed | G13: 26/08/2026 | H13: Vu Manh Dung | I13: Passed | J13: 26/08/2026 | K13: Vu Manh Dung | O13: Automated
A14: M3D-04 | B14: [Abnormal] A customer cannot request a 3D model for another store's product | C14: Send POST /api/products/{id}/model-3d/requests as a customer | D14: Returns 403 Forbidden | E14: A product owned by the caller, carrying at least one image | F14: Passed | G14: 26/08/2026 | H14: Vu Manh Dung | I14: Passed | J14: 26/08/2026 | K14: Vu Manh Dung | O14: Automated
A15: M3D-05 | B15: [Normal] The owner sees their own request in the product request list | C15: Send GET /api/products/{id}/model-3d/requests as a garden owner | D15: Returns 200 OK and the item is present in the returned collection | E15: A product owned by the caller, carrying at least one image | F15: Passed | G15: 26/08/2026 | H15: Vu Manh Dung | I15: Passed | J15: 26/08/2026 | K15: Vu Manh Dung | O15: Automated
A16: M3D-06 | B16: [Normal] Platform staff sees the pending request in the queue | C16: Send GET /api/model3d-requests as platform staff | D16: Returns 200 OK and the item is present in the returned collection | E16: A product owned by the caller, carrying at least one image | F16: Passed | G16: 26/08/2026 | H16: Vu Manh Dung | I16: Passed | J16: 26/08/2026 | K16: Vu Manh Dung | O16: Automated
A17: M3D-07 | B17: [Abnormal] A garden owner cannot open the platform-wide 3D queue | C17: Send GET /api/model3d-requests as a garden owner | D17: Returns 403 Forbidden | E17: None | F17: Passed | G17: 26/08/2026 | H17: Vu Manh Dung | I17: Passed | J17: 26/08/2026 | K17: Vu Manh Dung | O17: Automated
A18: M3D-08 | B18: [Normal] Staff generates the model and the request moves to InProgress | C18: See the test method for the exact call sequence | D18: Returns 202 Accepted and status = InProgress | E18: A product owned by the caller, carrying at least one image | F18: Passed | G18: 26/08/2026 | H18: Vu Manh Dung | I18: Passed | J18: 26/08/2026 | K18: Vu Manh Dung | O18: Automated
A19: M3D-09 | B19: [Normal] The preview of an in-progress request reports the provider state | C19: Send GET /api/model3d-requests/{id}/preview as platform staff | D19: Returns 200 OK and state = Succeeded | E19: A product owned by the caller, carrying at least one image | F19: Passed | G19: 26/08/2026 | H19: Vu Manh Dung | I19: Passed | J19: 26/08/2026 | K19: Vu Manh Dung | O19: Automated
A20: M3D-10 | B20: [Abnormal] Previewing a request that was never generated returns 409 | C20: Send GET /api/model3d-requests/{id}/preview as platform staff | D20: Returns 409 Conflict | E20: A product owned by the caller, carrying at least one image | F20: Passed | G20: 26/08/2026 | H20: Vu Manh Dung | I20: Passed | J20: 26/08/2026 | K20: Vu Manh Dung | O20: Automated
A21: M3D-11 | B21: [Normal] Accepting an in-progress request publishes the model on the product | C21: Send POST /api/model3d-requests/{id}/accept as an anonymous caller | D21: Returns 200 OK and status = Succeeded, the item is present in the returned collection | E21: A product owned by the caller, carrying at least one image | F21: Passed | G21: 26/08/2026 | H21: Vu Manh Dung | I21: Passed | J21: 26/08/2026 | K21: Vu Manh Dung | O21: Automated
A22: M3D-12 | B22: [Abnormal] Accepting a request that has not been generated returns 409 | C22: Send POST /api/model3d-requests/{id}/accept as platform staff | D22: Returns 409 Conflict | E22: A product owned by the caller, carrying at least one image | F22: Passed | G22: 26/08/2026 | H22: Vu Manh Dung | I22: Passed | J22: 26/08/2026 | K22: Vu Manh Dung | O22: Automated
... A31: M3D-21 | B31: [Abnormal] An image that carries a 3D model cannot be deleted | C31: Send POST /api/products/{id}/images/link as a customer | D31: Returns 409 Conflict | E31: A product owned by the caller, carrying at least one image | F31: Passed | G31: 26/08/2026 | H31: Vu Manh Dung | I31: Passed | J31: 26/08/2026 | K31: Vu Manh Dung | O31: Automated

Sheet Store and Staff
A2: Feature | B2: Store and Staff | R2: Passed
A3: Test requirement | B3: UC-02, UC-03. Garden store self-registration, pickup address, co-owners, the staff invitation lifecycle and store statistics. | R3: Failed
A4: Number of TCs | B4: =COUNTA(B11:B2023) -> 32 | R4: Pending
A5: Testing Round | B5: Passed | C5: Failed | D5: Pending | E5: N/A | R5: N/A
A6: Round 1 | B6: =COUNTIF($F$11:$F$2023,B$5) -> 32 | C6: =COUNTIF($F$11:$F$2023,C$5) -> 0 | D6: =COUNTIF($F$11:$F$2023,D$5) -> 0 | E6: =COUNTIF($F$11:$F$2023,E$5) -> 0
A7: Round 2 | B7: =COUNTIF($I$11:$I$2023,B$5) -> 32 | C7: =COUNTIF($I$11:$I$2023,C$5) -> 0 | D7: =COUNTIF($I$11:$I$2023,D$5) -> 0 | E7: =COUNTIF($I$11:$I$2023,E$5) -> 0
A8: Round 3 | B8: =COUNTIF($L$11:$L$2023,B$5) -> 0 | C8: =COUNTIF($L$11:$L$2023,C$5) -> 0 | D8: =COUNTIF($L$11:$L$2023,D$5) -> 0 | E8: =COUNTIF($L$11:$L$2023,E$5) -> 0
